Workbook

Sheet Unique Learners List
A1: First name | B1: Last name | C1: Email | D1: Contact phone | E1: Is Paid and Interested? | F1: Missing Assignments | G1: Call Status | H1: Comment
A2: Destaw Gisme | B2: Mulachew | C2: destawg@gmail.com | D2: +251918489684 | E2: =IF(ISNUMBER(MATCH(C2, 'Paid and Interested'!C:C, 0)), "Yes", "No") -> No | F2: Practice Quiz: Week 9, Week 9 Quiz, Week 9 Milestone, Week 9 Test
A3: Bitew | B3: Ababayehu | C3: bict1626@gmail.com | D3: +251949625344 | E3: =IF(ISNUMBER(MATCH(C3, 'Paid and Interested'!C:C, 0)), "Yes", "No") -> No | F3: Week 9 Milestone, Week 9 Test, Practice Quiz: Week 9, Week 9 Quiz
A4: Yitbarek | B4: Denbu | C4: yitbareksebsibe9@gmail.com | D4: 919410818 | E4: =IF(ISNUMBER(MATCH(C4, 'Paid and Interested'!C:C, 0)), "Yes", "No") -> No | F4: Week 9 Milestone, Week 9 Test, Practice Quiz: Week 9, Week 9 Quiz
A5: Mubarek | B5: Hassen | C5: mubeman63@gmail.com | D5: +251965030079 | E5: =IF(ISNUMBER(MATCH(C5, 'Paid and Interested'!C:C, 0)), "Yes", "No") -> No | F5: Week 9 Milestone, Week 9 Test, Practice Quiz: Week 9, Week 9 Quiz
A6: yoseph legesse | B6: abrha | C6: aregawiesayas@gmail.com | D6: +251996165586 | E6: =IF(ISNUMBER(MATCH(C6, 'Paid and Interested'!C:C, 0)), "Yes", "No") -> No | F6: Week 9 Milestone, Week 9 Test, Practice Quiz: Week 9, Week 9 Quiz
A7: abenezer | B7: Melsew | C7: abenezer.melsew@gmail.com | D7: +251913176044 | E7: =IF(ISNUMBER(MATCH(C7, 'Paid and Interested'!C:C, 0)), "Yes", "No") -> No | F7: Week 9 Milestone, Week 9 Test, Practice Quiz: Week 9, Week 9 Quiz
A8: Muzeyfi | B8: Mahadi | C8: mmuzeyfi@gmail.com | D8: +251975284215 | E8: =IF(ISNUMBER(MATCH(C8, 'Paid and Interested'!C:C, 0)), "Yes", "No") -> No | F8: Week 9 Milestone, Week 9 Test, Practice Quiz: Week 9, Week 9 Quiz
A9: Tedilahun Tesfaye | B9: Wada | C9: tedilahuntesfaye65@gmail.com | D9: +251939716065 | E9: =IF(ISNUMBER(MATCH(C9, 'Paid and Interested'!C:C, 0)), "Yes", "No") -> No | F9: Week 9 Milestone, Week 9 Test, Practice Quiz: Week 9, Week 9 Quiz
A10: Nebil | B10: Ahmed | C10: nebilnasir24@gmail.com | D10: +251994101121 | E10: =IF(ISNUMBER(MATCH(C10, 'Paid and Interested'!C:C, 0)), "Yes", "No") -> No | F10: Week 9 Milestone, Week 9 Test, Practice Quiz: Week 9, Week 9 Quiz
A11: Siraj | B11: Hassen | C11: sifrajhassen@gmail.com | D11: +251984131188 | E11: =IF(ISNUMBER(MATCH(C11, 'Paid and Interested'!C:C, 0)), "Yes", "No") -> No | F11: Week 9 Milestone, Week 9 Test, Practice Quiz: Week 9, Week 9 Quiz
A12: Addis | B12: Nigatu | C12: addishailu992@gmail.com | D12: +251945961714 | E12: =IF(ISNUMBER(MATCH(C12, 'Paid and Interested'!C:C, 0)), "Yes", "No") -> No | F12: Week 9 Milestone, Week 9 Test, Practice Quiz: Week 9, Week 9 Quiz
A13: Biruk Abera | B13: Gebra | C13: birukaberagebra@gmail.com | D13: +251929346733 | E13: =IF(ISNUMBER(MATCH(C13, 'Paid and Interested'!C:C, 0)), "Yes", "No") -> No | F13: Practice Quiz: Week 9, Week 9 Quiz, Week 9 Milestone, Week 9 Test
A14: Yohannis | B14: Million | C14: yohannismillion003@gmail.com | D14: +251994943497 | E14: =IF(ISNUMBER(MATCH(C14, 'Paid and Interested'!C:C, 0)), "Yes", "No") -> No | F14: Week 9 Milestone, Week 9 Test, Practice Quiz: Week 9, Week 9 Quiz
A15: Habtamu | B15: Mune | C15: habtamu122124s@gmail.com | D15: +251939778240 | E15: =IF(ISNUMBER(MATCH(C15, 'Paid and Interested'!C:C, 0)), "Yes", "No") -> No | F15: Week 9 Milestone, Week 9 Test, Practice Quiz: Week 9, Week 9 Quiz
A16: Ruth | B16: Getu | C16: rudygetu88@gmail.com | D16: +251944714263 | E16: =IF(ISNUMBER(MATCH(C16, 'Paid and Interested'!C:C, 0)), "Yes", "No") -> No | F16: Practice Quiz: Week 9, Week 9 Quiz, Week 9 Milestone, Week 9 Test
... A33: Ayantu | B33: Tariku | C33: ayantutariku22@gmail.com | D33: +251919473298 | E33: =IF(ISNUMBER(MATCH(C33, 'Paid and Interested'!C:C, 0)), "Yes", "No") -> No | F33: Week 9 Milestone, Week 9 Test, Practice Quiz: Week 9, Week 9 Quiz
A34: ezana | B34: ketema | C34: ezanaketema22@gmail.com | D34: 251934432842 | E34: =IF(ISNUMBER(MATCH(C34, 'Paid and Interested'!C:C, 0)), "Yes", "No") -> No | F34: Practice Quiz: Week 9, Week 9 Quiz, Week 9 Milestone, Week 9 Test
A35: Feven Solomon | B35: Aragaw | C35: dagimyilma@gmail.com | D35: +251703172769 | E35: =IF(ISNUMBER(MATCH(C35, 'Paid and Interested'!C:C, 0)), "Yes", "No") -> No | F35: Week 9 Milestone, Week 9 Test, Practice Quiz: Week 9, Week 9 Quiz
A36: Efrata | B36: Abayneh | C36: efratatewodros0@gmail.com | D36: +251904577470 | E36: =IF(ISNUMBER(MATCH(C36, 'Paid and Interested'!C:C, 0)), "Yes", "No") -> No | F36: Week 9 Milestone, Week 9 Test, Practice Quiz: Week 9, Week 9 Quiz
A37: Tola | B37: Oromia | C37: tolawestern27@gmail.com | D37: +251900595205 | E37: =IF(ISNUMBER(MATCH(C37, 'Paid and Interested'!C:C, 0)), "Yes", "No") -> No | F37: Week 9 Milestone, Week 9 Test, Practice Quiz: Week 9, Week 9 Quiz
A38: Rediet | B38: Negash | C38: redhamikael@gmail.com | D38: +251942953765 | E38: =IF(ISNUMBER(MATCH(C38, 'Paid and Interested'!C:C, 0)), "Yes", "No") -> No | F38: Week 9 Milestone, Week 9 Test, Practice Quiz: Week 9, Week 9 Quiz
A39: amanuel | B39: Ayalew | C39: amanueltesfaye544@gmail.com | D39: 942218249 | E39: =IF(ISNUMBER(MATCH(C39, 'Paid and Interested'!C:C, 0)), "Yes", "No") -> No | F39: Week 9 Milestone, Week 9 Test, Practice Quiz: Week 9, Week 9 Quiz
A40: Kirubel | B40: Hailu | C40: kirubel.seifu.great@gmail.com | D40: 909780413 | E40: =IF(ISNUMBER(MATCH(C40, 'Paid and Interested'!C:C, 0)), "Yes", "No") -> No | F40: Week 9 Milestone, Week 9 Test, Practice Quiz: Week 9, Week 9 Quiz
A41: Ermias | B41: Gebeyehu | C41: demekegebeyehu5@gmail.com | D41: +251920256167 | E41: =IF(ISNUMBER(MATCH(C41, 'Paid and Interested'!C:C, 0)), "Yes", "No") -> No | F41: Week 9 Milestone, Week 9 Test, Practice Quiz: Week 9, Week 9 Quiz
A42: Lielena | B42: Mesfin | C42: lielnams2006@gmail.com | D42: +251974400747 | E42: =IF(ISNUMBER(MATCH(C42, 'Paid and Interested'!C:C, 0)), "Yes", "No") -> No | F42: Week 9 Milestone, Week 9 Test, Practice Quiz: Week 9, Week 9 Quiz
A43: Naol | B43: Degol | C43: naolde812@gmail.com | D43: +251976029568 | E43: =IF(ISNUMBER(MATCH(C43, 'Paid and Interested'!C:C, 0)), "Yes", "No") -> No | F43: Week 9 Milestone, Week 9 Test, Practice Quiz: Week 9, Week 9 Quiz
A44: Sitra | B44: Yazew | C44: sitramasreshay@gmail.com | D44: +251973414100 | E44: =IF(ISNUMBER(MATCH(C44, 'Paid and Interested'!C:C, 0)), "Yes", "No") -> No | F44: Week 9 Milestone, Week 9 Test, Practice Quiz: Week 9, Week 9 Quiz
A45: Seidu | B45: Zayede | C45: seiduzayede@gmail.com | D45: +251921795959 | E45: =IF(ISNUMBER(MATCH(C45, 'Paid and Interested'!C:C, 0)), "Yes", "No") -> No | F45: Week 9 Milestone, Week 9 Test, Practice Quiz: Week 9, Week 9 Quiz
A46: Habiba | B46: Ashref | C46: ashrefhabiba08@gmail.com | D46: +251912382222 | E46: =IF(ISNUMBER(MATCH(C46, 'Paid and Interested'!C:C, 0)), "Yes", "No") -> No | F46: Week 9 Milestone, Week 9 Test, Practice Quiz: Week 9, Week 9 Quiz
A47: Hakimiyas | B47: Yilma | C47: kemeshgale@gmail.com | D47: 911918308 | E47: =IF(ISNUMBER(MATCH(C47, 'Paid and Interested'!C:C, 0)), "Yes", "No") -> No | F47: Practice Quiz: Week 9, Week 9 Quiz, Week 9 Milestone, Week 9 Test
A48: Nahom | B48: Zeleke | C48: nahomzeleke5@gmail.com | D48: +251989033620 | E48: =IF(ISNUMBER(MATCH(C48, 'Paid and Interested'!C:C, 0)), "Yes", "No") -> No | F48: Week 9 Milestone, Week 9 Test, Practice Quiz: Week 9, Week 9 Quiz
A49: Mikiyas | B49: Muluneh | C49: mulumiki4@gmail.com | D49: +251927990402 | E49: =IF(ISNUMBER(MATCH(C49, 'Paid and Interested'!C:C, 0)), "Yes", "No") -> No | F49: Week 9 Milestone, Week 9 Test, Practice Quiz: Week 9, Week 9 Quiz
A50: Kirubel | B50: Tesfaye | C50: tkirubel648@gmail.com | D50: +251939993088 | E50: =IF(ISNUMBER(MATCH(C50, 'Paid and Interested'!C:C, 0)), "Yes", "No") -> No | F50: Week 9 Milestone, Week 9 Test, Practice Quiz: Week 9, Week 9 Quiz
A51: Meron | B51: Tanjerina | C51: merontangu@gmail.com | D51: +251911135410 | E51: =IF(ISNUMBER(MATCH(C51, 'Paid and Interested'!C:C, 0)), "Yes", "No") -> No | F51: Week 9 Milestone, Week 9 Test, Practice Quiz: Week 9, Week 9 Quiz
A52: yohannes | B52: kebede | C52: yohaneskebedejo15@gmail.com | D52: +251935551413 | E52: =IF(ISNUMBER(MATCH(C52, 'Paid and Interested'!C:C, 0)), "Yes", "No") -> No | F52: Week 9 Milestone, Week 9 Test, Practice Quiz: Week 9, Week 9 Quiz
A53: Biniyam | B53: Mandefro | C53: biniman286@gmail.com | D53: +251979078288 | E53: =IF(ISNUMBER(MATCH(C53, 'Paid and Interested'!C:C, 0)), "Yes", "No") -> No | F53: Week 9 Milestone, Week 9 Test, Practice Quiz: Week 9, Week 9 Quiz
A54: Intisar | B54: Shemsu | C54: intisarshemsu2017gmail.com@gmail.com | D54: +251975184414 | E54: =IF(ISNUMBER(MATCH(C54, 'Paid and Interested'!C:C, 0)), "Yes", "No") -> No | F54: Week 9 Milestone, Week 9 Test, Practice Quiz: Week 9, Week 9 Quiz
A55: Yordanos | B55: Shemsedien | C55: yordanosshemsedin901@gmail.com | D55: +251901859818 | E55: =IF(ISNUMBER(MATCH(C55, 'Paid and Interested'!C:C, 0)), "Yes", "No") -> No | F55: Week 9 Milestone, Week 9 Test, Practice Quiz: Week 9, Week 9 Quiz
A56: REDIET TILAHUN | B56: AYELE | C56: rediettilahun10@gmail.com | D56: +251911172398 | E56: =IF(ISNUMBER(MATCH(C56, 'Paid and Interested'!C:C, 0)), "Yes", "No") -> No | F56: Week 9 Milestone, Week 9 Test, Practice Quiz: Week 9, Week 9 Quiz
...

Sheet All
A2: yoseph legesse | B2: abrha | C2: aregawiesayas@gmail.com | D2: +251996165586 | E2: Wrong Person
A3: ezana | B3: ketema | C3: ezanaketema22@gmail.com | D3: 251934432842 | E3: Reached
A4: Destaw Gisme | B4: Mulachew | C4: destawg@gmail.com | D4: +251918489684 | E4: Reached
A5: Bitew | B5: Ababayehu | C5: bict1626@gmail.com | D5: +251949625344 | E5: Reached
A6: Yitbarek | B6: Denbu | C6: yitbareksebsibe9@gmail.com | D6: 919410818 | E6: Reached
A7: Mubarek | B7: Hassen | C7: mubeman63@gmail.com | D7: +251965030079 | E7: Reached
A8: Muzeyfi | B8: Mahadi | C8: mmuzeyfi@gmail.com | D8: +251975284215 | E8: Reached
A9: Nebil | B9: Ahmed | C9: nebilnasir24@gmail.com | D9: +251994101121 | E9: Reached
A10: Siraj | B10: Hassen | C10: sifrajhassen@gmail.com | D10: +251984131188 | E10: Reached
A11: Addis | B11: Nigatu | C11: addishailu992@gmail.com | D11: +251945961714 | E11: Reached
A12: Biruk Abera | B12: Gebra | C12: birukaberagebra@gmail.com | D12: +251929346733 | E12: Reached
A13: Yohannis | B13: Million | C13: yohannismillion003@gmail.com | D13: +251994943497 | E13: Reached
A14: Habtamu | B14: Mune | C14: habtamu122124s@gmail.com | D14: +251939778240 | E14: Reached
A15: Ruth | B15: Getu | C15: rudygetu88@gmail.com | D15: +251944714263 | E15: Reached
A16: Gedion | B16: Kifle | C16: gedionkifle0@gmail.com | D16: +251961099526 | E16: Reached
A17: Meron | B17: Zelalem | C17: haymikebede3@gmail.com | D17: +251929259929 | E17: Reached
A18: Bemnet | B18: Engdashet | C18: bemnetengda45@gmail.com | D18: +251912206321 | E18: Reached
... A23: Gidyelem | B23: Kelecha | C23: shibugidyelem@gmail.com | D23: +251992524875 | E23: Reached
A24: Kirubel | B24: Hailu | C24: kirubel.seifu.great@gmail.com | D24: 909780413 | E24: Reached
A25: Naol | B25: Degol | C25: naolde812@gmail.com | D25: +251976029568 | E25: Reached
A26: Habiba | B26: Ashref | C26: ashrefhabiba08@gmail.com | D26: +251912382222 | E26: Reached
A27: Hakimiyas | B27: Yilma | C27: kemeshgale@gmail.com | D27: 911918308 | E27: Reached
A28: Mikiyas | B28: Muluneh | C28: mulumiki4@gmail.com | D28: +251927990402 | E28: Reached
A29: Kirubel | B29: Tesfaye | C29: tkirubel648@gmail.com | D29: +251939993088 | E29: Reached
A30: yohannes | B30: kebede | C30: yohaneskebedejo15@gmail.com | D30: +251935551413 | E30: Reached
A31: Intisar | B31: Shemsu | C31: intisarshemsu2017gmail.com@gmail.com | D31: +251975184414 | E31: Reached
A32: Yordanos | B32: Shemsedien | C32: yordanosshemsedin901@gmail.com | D32: +251901859818 | E32: Reached
A33: REDIET TILAHUN | B33: AYELE | C33: rediettilahun10@gmail.com | D33: +251911172398 | E33: Reached
A34: Mengistu | B34: Tegegne | C34: tegegnem83@gmail.com | D34: 919698237 | E34: Reached
A35: Blen | B35: Gebremariam | C35: bilublen20@gmail.com | D35: +251966888442 | E35: Reached
A36: Misganaw | B36: Yehuala | C36: asnakemisgana88@gmail.com | D36: +251913618893 | E36: Reached
A37: Hanan | B37: Kebede | C37: hananitakebede12@gmail.com | D37: +251946409290 | E37: Reached
A38: Werkineh Gebermichael | B38: Welde | C38: werkinehgmichael10@gmail.com | D38: +251903096549 | E38: Reached
A39: Getnet | B39: Demissie | C39: getnetmulugeta2000@gmail.com | D39: 964865694 | E39: Reached
A40: Dagmawi | B40: Tesfaye | C40: dagmawitesfaye1318@gmail.com | D40: +251919183460 | E40: Reached
A41: Leul | B41: Yonas | C41: lecrae12345678@gmail.com | D41: +251909121415 | E41: Reached
A42: Ruth | B42: Getachew | C42: ruthgetachew49@gmail.com | D42: +251946362757 | E42: Reached
A43: Kenesa | B43: Tesfaye | C43: travtube43@gmail.com | D43: +251977840440 | E43: Reached
A44: Eliyas | B44: Dejena | C44: eliyasdejena96@gmail.com | D44: +251991122060 | E44: Reached
A45: Kaleb | B45: berhane | C45: kalebberhane4@gmail.com | D45: +251940123511 | E45: Reached
...

Sheet Tsedenia
A1: yoseph legesse | B1: abrha | C1: aregawiesayas@gmail.com | D1: +251996165586 | E1: =IF(ISNUMBER(MATCH(C1, 'Paid and Interested'!C:C, 0)), "Yes", "No") -> No | F1: Week 9 Milestone, Week 9 Test, Practice Quiz: Week 9, Week 9 Quiz | G1: Pathway | H1: Wrong Person
A2: ezana | B2: ketema | C2: ezanaketema22@gmail.com | D2: 251934432842 | E2: =IF(ISNUMBER(MATCH(C2, 'Paid and Interested'!C:C, 0)), "Yes", "No") -> No | F2: Practice Quiz: Week 9, Week 9 Quiz, Week 9 Milestone, Week 9 Test | G2: Pathway | H2: Reached | I2: he said okay
A3: Destaw Gisme | B3: Mulachew | C3: destawg@gmail.com | D3: +251918489684 | E3: =IF(ISNUMBER(MATCH(C3, 'Paid and Interested'!C:C, 0)), "Yes", "No") -> No | F3: Practice Quiz: Week 9, Week 9 Quiz, Week 9 Milestone, Week 9 Test | G3: Pathway | H3: Reached | I3: he said okay
A4: Bitew | B4: Ababayehu | C4: bict1626@gmail.com | D4: +251949625344 | E4: =IF(ISNUMBER(MATCH(C4, 'Paid and Interested'!C:C, 0)), "Yes", "No") -> No | F4: Week 9 Milestone, Week 9 Test, Practice Quiz: Week 9, Week 9 Quiz | G4: Pathway | H4: Reached | I4: he said okay
A5: Yitbarek | B5: Denbu | C5: yitbareksebsibe9@gmail.com | D5: 919410818 | E5: =IF(ISNUMBER(MATCH(C5, 'Paid and Interested'!C:C, 0)), "Yes", "No") -> No | F5: Week 9 Milestone, Week 9 Test, Practice Quiz: Week 9, Week 9 Quiz | G5: Pathway | H5: Reached | I5: he said okay
A6: Mubarek | B6: Hassen | C6: mubeman63@gmail.com | D6: +251965030079 | E6: =IF(ISNUMBER(MATCH(C6, 'Paid and Interested'!C:C, 0)), "Yes", "No") -> No | F6: Week 9 Milestone, Week 9 Test, Practice Quiz: Week 9, Week 9 Quiz | G6: Pathway | H6: Reached | I6: he has paused the course
A7: Muzeyfi | B7: Mahadi | C7: mmuzeyfi@gmail.com | D7: +251975284215 | E7: =IF(ISNUMBER(MATCH(C7, 'Paid and Interested'!C:C, 0)), "Yes", "No") -> No | F7: Week 9 Milestone, Week 9 Test, Practice Quiz: Week 9, Week 9 Quiz | G7: Pathway | H7: Reached | I7: he said okay
A8: Nebil | B8: Ahmed | C8: nebilnasir24@gmail.com | D8: +251994101121 | E8: =IF(ISNUMBER(MATCH(C8, 'Paid and Interested'!C:C, 0)), "Yes", "No") -> No | F8: Week 9 Milestone, Week 9 Test, Practice Quiz: Week 9, Week 9 Quiz | G8: Pathway | H8: Reached | I8: he said okay
A9: Siraj | B9: Hassen | C9: sifrajhassen@gmail.com | D9: +251984131188 | E9: =IF(ISNUMBER(MATCH(C9, 'Paid and Interested'!C:C, 0)), "Yes", "No") -> No | F9: Week 9 Milestone, Week 9 Test, Practice Quiz: Week 9, Week 9 Quiz | G9: Pathway | H9: Reached | I9: he is outside from Addis
A10: Addis | B10: Nigatu | C10: addishailu992@gmail.com | D10: +251945961714 | E10: =IF(ISNUMBER(MATCH(C10, 'Paid and Interested'!C:C, 0)), "Yes", "No") -> No | F10: Week 9 Milestone, Week 9 Test, Practice Quiz: Week 9, Week 9 Quiz | G10: Pathway | H10: Reached | I10: he said okay
A11: Biruk Abera | B11: Gebra | C11: birukaberagebra@gmail.com | D11: +251929346733 | E11: =IF(ISNUMBER(MATCH(C11, 'Paid and Interested'!C:C, 0)), "Yes", "No") -> No | F11: Practice Quiz: Week 9, Week 9 Quiz, Week 9 Milestone, Week 9 Test | G11: Pathway | H11: Reached | I11: he said okay
A12: Yohannis | B12: Million | C12: yohannismillion003@gmail.com | D12: +251994943497 | E12: =IF(ISNUMBER(MATCH(C12, 'Paid and Interested'!C:C, 0)), "Yes", "No") -> No | F12: Week 9 Milestone, Week 9 Test, Practice Quiz: Week 9, Week 9 Quiz | G12: Pathway | H12: Reached | I12: he's too busy to continue the course
A13: Habtamu | B13: Mune | C13: habtamu122124s@gmail.com | D13: +251939778240 | E13: =IF(ISNUMBER(MATCH(C13, 'Paid and Interested'!C:C, 0)), "Yes", "No") -> No | F13: Week 9 Milestone, Week 9 Test, Practice Quiz: Week 9, Week 9 Quiz | G13: Pathway | H13: Reached | I13: he's not intersted
A14: Ruth | B14: Getu | C14: rudygetu88@gmail.com | D14: +251944714263 | E14: =IF(ISNUMBER(MATCH(C14, 'Paid and Interested'!C:C, 0)), "Yes", "No") -> No | F14: Practice Quiz: Week 9, Week 9 Quiz, Week 9 Milestone, Week 9 Test | G14: Pathway | H14: Reached | I14: she's not interested
A15: Gedion | B15: Kifle | C15: gedionkifle0@gmail.com | D15: +251961099526 | E15: =IF(ISNUMBER(MATCH(C15, 'Paid and Interested'!C:C, 0)), "Yes", "No") -> No | F15: Week 9 Milestone, Week 9 Test, Practice Quiz: Week 9, Week 9 Quiz | G15: Pathway | H15: Reached | I15: he said okay
A16: Meron | B16: Zelalem | C16: haymikebede3@gmail.com | D16: +251929259929 | E16: =IF(ISNUMBER(MATCH(C16, 'Paid and Interested'!C:C, 0)), "Yes", "No") -> No | F16: Week 9 Milestone, Week 9 Test, Practice Quiz: Week 9, Week 9 Quiz | G16: Pathway | H16: Reached | I16: she said okay
A17: Bemnet | B17: Engdashet | C17: bemnetengda45@gmail.com | D17: +251912206321 | E17: =IF(ISNUMBER(MATCH(C17, 'Paid and Interested'!C:C, 0)), "Yes", "No") -> No | F17: Practice Quiz: Week 9, Week 9 Quiz, Week 9 Milestone, Week 9 Test | G17: Pathway | H17: Reached | I17: she isn't interested
... A22: Gidyelem | B22: Kelecha | C22: shibugidyelem@gmail.com | D22: +251992524875 | E22: =IF(ISNUMBER(MATCH(C22, 'Paid and Interested'!C:C, 0)), "Yes", "No") -> No | F22: Week 9 Milestone, Week 9 Test, Practice Quiz: Week 9, Week 9 Quiz | G22: Pathway | H22: Reached | I22: he's not interested
A23: Kirubel | B23: Hailu | C23: kirubel.seifu.great@gmail.com | D23: 909780413 | E23: =IF(ISNUMBER(MATCH(C23, 'Paid and Interested'!C:C, 0)), "Yes", "No") -> No | F23: Week 9 Milestone, Week 9 Test, Practice Quiz: Week 9, Week 9 Quiz | G23: Pathway | H23: Reached | I23: he said okay
A24: Naol | B24: Degol | C24: naolde812@gmail.com | D24: +251976029568 | E24: =IF(ISNUMBER(MATCH(C24, 'Paid and Interested'!C:C, 0)), "Yes", "No") -> No | F24: Week 9 Milestone, Week 9 Test, Practice Quiz: Week 9, Week 9 Quiz | G24: Pathway | H24: Reached | I24: he's not interested
A25: Habiba | B25: Ashref | C25: ashrefhabiba08@gmail.com | D25: +251912382222 | E25: =IF(ISNUMBER(MATCH(C25, 'Paid and Interested'!C:C, 0)), "Yes", "No") -> No | F25: Week 9 Milestone, Week 9 Test, Practice Quiz: Week 9, Week 9 Quiz | G25: Pathway | H25: Reached | I25: she wants to apply for the next cohort
A26: Hakimiyas | B26: Yilma | C26: kemeshgale@gmail.com | D26: 911918308 | E26: =IF(ISNUMBER(MATCH(C26, 'Paid and Interested'!C:C, 0)), "Yes", "No") -> No | F26: Practice Quiz: Week 9, Week 9 Quiz, Week 9 Milestone, Week 9 Test | G26: Pathway | H26: Reached | I26: he wants to apply for the next cohort
A27: Mikiyas | B27: Muluneh | C27: mulumiki4@gmail.com | D27: +251927990402 | E27: =IF(ISNUMBER(MATCH(C27, 'Paid and Interested'!C:C, 0)), "Yes", "No") -> No | F27: Week 9 Milestone, Week 9 Test, Practice Quiz: Week 9, Week 9 Quiz | G27: Pathway | H27: Reached | I27: he's not in Addis
A28: Kirubel | B28: Tesfaye | C28: tkirubel648@gmail.com | D28: +251939993088 | E28: =IF(ISNUMBER(MATCH(C28, 'Paid and Interested'!C:C, 0)), "Yes", "No") -> No | F28: Week 9 Milestone, Week 9 Test, Practice Quiz: Week 9, Week 9 Quiz | G28: Pathway | H28: Reached | I28: he wants to apply for the next cohort
A29: yohannes | B29: kebede | C29: yohaneskebedejo15@gmail.com | D29: +251935551413 | E29: =IF(ISNUMBER(MATCH(C29, 'Paid and Interested'!C:C, 0)), "Yes", "No") -> No | F29: Week 9 Milestone, Week 9 Test, Practice Quiz: Week 9, Week 9 Quiz | G29: Pathway | H29: Reached | I29: he's not in Addis
A30: Intisar | B30: Shemsu | C30: intisarshemsu2017gmail.com@gmail.com | D30: +251975184414 | E30: =IF(ISNUMBER(MATCH(C30, 'Paid and Interested'!C:C, 0)), "Yes", "No") -> No | F30: Week 9 Milestone, Week 9 Test, Practice Quiz: Week 9, Week 9 Quiz | G30: Pathway | H30: Reached | I30: she's not interested
A31: Yordanos | B31: Shemsedien | C31: yordanosshemsedin901@gmail.com | D31: +251901859818 | E31: =IF(ISNUMBER(MATCH(C31, 'Paid and Interested'!C:C, 0)), "Yes", "No") -> No | F31: Week 9 Milestone, Week 9 Test, Practice Quiz: Week 9, Week 9 Quiz | G31: Pathway | H31: Reached | I31: she's not in Addis
A32: REDIET TILAHUN | B32: AYELE | C32: rediettilahun10@gmail.com | D32: +251911172398 | E32: =IF(ISNUMBER(MATCH(C32, 'Paid and Interested'!C:C, 0)), "Yes", "No") -> No | F32: Week 9 Milestone, Week 9 Test, Practice Quiz: Week 9, Week 9 Quiz | G32: Pathway | H32: Reached | I32: he is too busy to continue the course
A33: Mengistu | B33: Tegegne | C33: tegegnem83@gmail.com | D33: 919698237 | E33: =IF(ISNUMBER(MATCH(C33, 'Paid and Interested'!C:C, 0)), "Yes", "No") -> No | F33: Week 9 Milestone, Week 9 Test, Practice Quiz: Week 9, Week 9 Quiz | G33: Pathway | H33: Reached | I33: he's not in Addis
A34: Blen | B34: Gebremariam | C34: bilublen20@gmail.com | D34: +251966888442 | E34: =IF(ISNUMBER(MATCH(C34, 'Paid and Interested'!C:C, 0)), "Yes", "No") -> No | F34: Week 9 Milestone, Week 9 Test, Practice Quiz: Week 9, Week 9 Quiz | G34: Pathway | H34: Reached | I34: she said okay
A35: Misganaw | B35: Yehuala | C35: asnakemisgana88@gmail.com | D35: +251913618893 | E35: =IF(ISNUMBER(MATCH(C35, 'Paid and Interested'!C:C, 0)), "Yes", "No") -> No | F35: Week 9 Milestone, Week 9 Test, Practice Quiz: Week 9, Week 9 Quiz | G35: Pathway | H35: Reached | I35: he will come to the hub
A36: Hanan | B36: Kebede | C36: hananitakebede12@gmail.com | D36: +251946409290 | E36: =IF(ISNUMBER(MATCH(C36, 'Paid and Interested'!C:C, 0)), "Yes", "No") -> No | F36: Week 9 Milestone, Week 9 Test, Practice Quiz: Week 9, Week 9 Quiz | G36: Pathway | H36: Reached | I36: email wasn't working
A37: Werkineh Gebermichael | B37: Welde | C37: werkinehgmichael10@gmail.com | D37: +251903096549 | E37: =IF(ISNUMBER(MATCH(C37, 'Paid and Interested'!C:C, 0)), "Yes", "No") -> No | F37: Week 9 Milestone, Week 9 Test, Practice Quiz: Week 9, Week 9 Quiz | G37: Pathway | H37: Reached | I37: he said okay
A38: Getnet | B38: Demissie | C38: getnetmulugeta2000@gmail.com | D38: 964865694 | E38: =IF(ISNUMBER(MATCH(C38, 'Paid and Interested'!C:C, 0)), "Yes", "No") -> No | F38: Week 9 Milestone, Week 9 Test, Practice Quiz: Week 9, Week 9 Quiz | G38: Pathway | H38: Reached | I38: he might finish the assignments
A39: Dagmawi | B39: Tesfaye | C39: dagmawitesfaye1318@gmail.com | D39: +251919183460 | E39: =IF(ISNUMBER(MATCH(C39, 'Paid and Interested'!C:C, 0)), "Yes", "No") -> No | F39: Week 9 Milestone, Week 9 Test, Practice Quiz: Week 9, Week 9 Quiz | G39: Pathway | H39: Reached | I39: he said okay
A40: Leul | B40: Yonas | C40: lecrae12345678@gmail.com | D40: +251909121415 | E40: =IF(ISNUMBER(MATCH(C40, 'Paid and Interested'!C:C, 0)), "Yes", "No") -> No | F40: Week 9 Milestone, Week 9 Test, Practice Quiz: Week 9, Week 9 Quiz | G40: Pathway | H40: Reached | I40: he's not interested
A41: Ruth | B41: Getachew | C41: ruthgetachew49@gmail.com | D41: +251946362757 | E41: =IF(ISNUMBER(MATCH(C41, 'Paid and Interested'!C:C, 0)), "Yes", "No") -> No | F41: Practice Quiz: Week 9, Week 9 Quiz, Week 9 Milestone, Week 9 Test | G41: Pathway | H41: Reached | I41: she's not in Addis
A42: Kenesa | B42: Tesfaye | C42: travtube43@gmail.com | D42: +251977840440 | E42: =IF(ISNUMBER(MATCH(C42, 'Paid and Interested'!C:C, 0)), "Yes", "No") -> No | F42: Week 9 Milestone, Week 9 Test, Practice Quiz: Week 9, Week 9 Quiz | G42: Pathway | H42: Reached | I42: he's not in Addis
A43: Eliyas | B43: Dejena | C43: eliyasdejena96@gmail.com | D43: +251991122060 | E43: =IF(ISNUMBER(MATCH(C43, 'Paid and Interested'!C:C, 0)), "Yes", "No") -> No | F43: Week 9 Milestone, Week 9 Test, Practice Quiz: Week 9, Week 9 Quiz | G43: Pathway | H43: Reached | I43: his email is not working
A44: Kaleb | B44: berhane | C44: kalebberhane4@gmail.com | D44: +251940123511 | E44: =IF(ISNUMBER(MATCH(C44, 'Paid and Interested'!C:C, 0)), "Yes", "No") -> No | F44: Week 9 Milestone, Week 9 Test, Practice Quiz: Week 9, Week 9 Quiz | G44: Pathway | H44: Reached | I44: he has paused the course
...

Sheet Yosef
A1: First name | B1: Last name | C1: Email | D1: Contact phone | E1: Is Paid and Interested? | F1: Missing Assignments | G1: Catagory | H1: Call Status | I1: Comment
A2: Ezana | B2: Mesfin | C2: nitroman1375@gmail.com | D2: +251966925114 | E2: =IF(ISNUMBER(MATCH(C2, 'Paid and Interested'!C:C, 0)), "Yes", "No") -> No | F2: Week 9 Milestone, Week 9 Test, Practice Quiz: Week 9, Week 9 Quiz | G2: Pathway | H2: Wrong Person
A3: HENOK | B3: JR | C3: jrhenok52@gmail.com | D3: +251953962514 | E3: =IF(ISNUMBER(MATCH(C3, 'Paid and Interested'!C:C, 0)), "Yes", "No") -> No | F3: Week 9 Milestone, Week 9 Test, Practice Quiz: Week 9, Week 9 Quiz | G3: Pathway | H3: Reached | I3: busy sceduled and cant submit
A4: Emanda | B4: Aweke | C4: emandaawekee@gmail.com | D4: +251911660398 | E4: =IF(ISNUMBER(MATCH(C4, 'Paid and Interested'!C:C, 0)), "Yes", "No") -> No | F4: Week 9 Milestone, Week 9 Test, Practice Quiz: Week 9, Week 9 Quiz | G4: Pathway | H4: Reached | I4: she will
A5: saimon | B5: taye | C5: yilfashewamekonnen@gmail.com | D5: +251920459750 | E5: =IF(ISNUMBER(MATCH(C5, 'Paid and Interested'!C:C, 0)), "Yes", "No") -> No | F5: Practice Quiz: Week 9, Week 9 Quiz, Week 9 Milestone, Week 9 Test | G5: Pathway | H5: Reached | I5: he is not in adiss and cant submit
A6: belay | B6: Zeleke | C6: belay6519@gmail.com | D6: +251952295180 | E6: =IF(ISNUMBER(MATCH(C6, 'Paid and Interested'!C:C, 0)), "Yes", "No") -> No | F6: Week 9 Milestone, Week 9 Test, Practice Quiz: Week 9, Week 9 Quiz | G6: Pathway | H6: Reached | I6: he is not interested
A7: Samuel | B7: Taye | C7: samueltaye126@gmail.com | D7: +251989975215 | E7: =IF(ISNUMBER(MATCH(C7, 'Paid and Interested'!C:C, 0)), "Yes", "No") -> No | F7: Week 9 Milestone, Week 9 Test, Practice Quiz: Week 9, Week 9 Quiz | G7: Pathway | H7: Reached | I7: he is not interested
A8: Yassir | B8: Hamza | C8: yassirhamzab@gmail.com | D8: +251940181950 | E8: =IF(ISNUMBER(MATCH(C8, 'Paid and Interested'!C:C, 0)), "Yes", "No") -> No | F8: Practice Quiz: Week 9, Week 9 Quiz, Week 9 Milestone, Week 9 Test | G8: Pathway | H8: Reached | I8: he is not interested
A9: lealem | B9: birhanu | C9: lealembirhanu1998@gmail.com | D9: +251996861688 | E9: =IF(ISNUMBER(MATCH(C9, 'Paid and Interested'!C:C, 0)), "Yes", "No") -> No | F9: Week 9 Milestone, Week 9 Test, Practice Quiz: Week 9, Week 9 Quiz | G9: Pathway | H9: Reached | I9: she will call back
A10: Noah | B10: Doju | C10: noahdoju@gmail.com | D10: +251942319040 | E10: =IF(ISNUMBER(MATCH(C10, 'Paid and Interested'!C:C, 0)), "Yes", "No") -> No | F10: Week 9 Milestone, Week 9 Test, Practice Quiz: Week 9, Week 9 Quiz | G10: Pathway | H10: Reached | I10: he cant couse he not in adiss
A11: Yeabsira Kayel | B11: Wube | C11: yeabkalkayel@gmail.com | D11: +251988397119 | E11: =IF(ISNUMBER(MATCH(C11, 'Paid and Interested'!C:C, 0)), "Yes", "No") -> No | F11: Week 9 Milestone, Week 9 Test, Practice Quiz: Week 9, Week 9 Quiz | G11: Pathway | H11: Reached | I11: he needs the program for next chort
A12: Roza | B12: Demisew | C12: rozademisew3@gmail.com | D12: +251912676385 | E12: =IF(ISNUMBER(MATCH(C12, 'Paid and Interested'!C:C, 0)), "Yes", "No") -> No | F12: Week 9 Milestone, Week 9 Test, Practice Quiz: Week 9, Week 9 Quiz | G12: Pathway | H12: Reached | I12: busy sceduled so she cant continue
A13: Filimon | B13: Tadewos | C13: manfili330@gmail.com | D13: +251965802255 | E13: =IF(ISNUMBER(MATCH(C13, 'Paid and Interested'!C:C, 0)), "Yes", "No") -> No | F13: Week 9 Milestone, Week 9 Test, Practice Quiz: Week 9, Week 9 Quiz | G13: Pathway | H13: Reached | I13: he will
A14: Besufkad | B14: Tadesse | C14: tsbese101@gmail.com | D14: +251984006778 | E14: =IF(ISNUMBER(MATCH(C14, 'Paid and Interested'!C:C, 0)), "Yes", "No") -> No | F14: Week 9 Milestone, Week 9 Test, Practice Quiz: Week 9, Week 9 Quiz | G14: Pathway | H14: Reached | I14: busy sceduled so he cant continue
... A24: Huda | B24: Abdullah | C24: ha7125416@gmail.com | D24: +251936267829 | E24: =IF(ISNUMBER(MATCH(C24, 'Paid and Interested'!C:C, 0)), "Yes", "No") -> No | F24: Practice Quiz: Week 9, Week 9 Quiz, Week 9 Milestone, Week 9 Test | G24: Pathway | H24: Reached | I24: busy sceduled and cant continue
A25: Yonatan | B25: Menase | C25: yonatan.menase@gmail.com | D25: 983885611 | E25: =IF(ISNUMBER(MATCH(C25, 'Paid and Interested'!C:C, 0)), "Yes", "No") -> No | F25: Practice Quiz: Week 9, Week 9 Quiz, Week 9 Milestone, Week 9 Test | G25: Pathway | H25: Reached | I25: busy sceduled and cant continue
A26: Yetemegnehuat | B26: Ejara | C26: yetm2017@gmail.com | D26: +251935034873 | E26: =IF(ISNUMBER(MATCH(C26, 'Paid and Interested'!C:C, 0)), "Yes", "No") -> No | F26: Week 9 Milestone, Week 9 Test, Practice Quiz: Week 9, Week 9 Quiz | G26: Pathway | H26: Reached | I26: not in adiss
A27: Wintana | B27: Dereje | C27: doriasu315@gmail.com | D27: +251937920670 | E27: =IF(ISNUMBER(MATCH(C27, 'Paid and Interested'!C:C, 0)), "Yes", "No") -> No | F27: Practice Quiz: Week 9, Week 9 Quiz, Week 9 Milestone, Week 9 Test | G27: Pathway | H27: Reached | I27: busy sceduled so cant continue
A28: NOBEL | B28: MUSSIE | C28: novamgt21@gmail.com | D28: +251906020763 | E28: =IF(ISNUMBER(MATCH(C28, 'Paid and Interested'!C:C, 0)), "Yes", "No") -> No | F28: Week 9 Milestone, Week 9 Test, Practice Quiz: Week 9, Week 9 Quiz | G28: Pathway | H28: Reached | I28: they will pass the message
A29: Wengel | B29: Awit | C29: wengela89@gmail.com | D29: +251964466466 | E29: =IF(ISNUMBER(MATCH(C29, 'Paid and Interested'!C:C, 0)), "Yes", "No") -> No | F29: Week 9 Milestone, Week 9 Test, Practice Quiz: Week 9, Week 9 Quiz | G29: Pathway | H29: Reached | I29: she not in adiss
A30: Warobe | B30: Girma | C30: warobewawa@gmail.com | D30: +251936506850 | E30: =IF(ISNUMBER(MATCH(C30, 'Paid and Interested'!C:C, 0)), "Yes", "No") -> No | F30: Week 9 Milestone, Week 9 Test, Practice Quiz: Week 9, Week 9 Quiz | G30: Pathway | H30: Reached | I30: not in adiss
A31: NATNAEL | B31: TILAHUN | C31: nman44183@gmail.com | D31: +251901095333 | E31: =IF(ISNUMBER(MATCH(C31, 'Paid and Interested'!C:C, 0)), "Yes", "No") -> No | F31: Week 9 Milestone | G31: Pathway | H31: Reached | I31: he will
A32: Amen | B32: Wakjira | C32: amenwakjirab@gmail.com | D32: she will | E32: =IF(ISNUMBER(MATCH(C32, 'Paid and Interested'!C:C, 0)), "Yes", "No") -> No | F32: Week 9 Milestone, Week 9 Test, Practice Quiz: Week 9, Week 9 Quiz | G32: Pathway | H32: Reached
A33: Lamrot | B33: Zeyede | C33: lamrotzed@gmail.com | D33: +251902477012 | E33: =IF(ISNUMBER(MATCH(C33, 'Paid and Interested'!C:C, 0)), "Yes", "No") -> No | F33: Week 9 Milestone, Week 9 Test, Practice Quiz: Week 9, Week 9 Quiz | G33: Pathway | H33: Reached | I33: busy sceduled so can continue
A34: Nahusenay Gebreslasie | B34: Bzuayene | C34: nahusenay.bzuayene@gmail.com | D34: +251928748783 | E34: =IF(ISNUMBER(MATCH(C34, 'Paid and Interested'!C:C, 0)), "Yes", "No") -> No | F34: Week 9 Milestone, Week 9 Test, Practice Quiz: Week 9, Week 9 Quiz | G34: Pathway | H34: Reached | I34: busy sceduled so can continue
A35: Dagim | B35: Kindu | C35: dagimkindu2t@gmail.com | D35: +251960836912 | E35: =IF(ISNUMBER(MATCH(C35, 'Paid and Interested'!C:C, 0)), "Yes", "No") -> No | F35: Practice Quiz: Week 9, Week 9 Quiz, Week 9 Milestone, Week 9 Test | G35: Pathway | H35: Reached | I35: busy sceduled so can continue
A36: Dagimawi | B36: Geberesillasie | C36: mandagi588@gmail.com | D36: +251943133459 | E36: =IF(ISNUMBER(MATCH(C36, 'Paid and Interested'!C:C, 0)), "Yes", "No") -> No | F36: Practice Quiz: Week 9, Week 9 Quiz, Week 9 Milestone | G36: Pathway | H36: Reached | I36: he will
A37: Dagmawi | B37: Tewodros | C37: yimegnutalasefa@gmail.com | D37: 960306801 | E37: =IF(ISNUMBER(MATCH(C37, 'Paid and Interested'!C:C, 0)), "Yes", "No") -> No | F37: Practice Quiz: Week 9, Week 9 Quiz, Week 9 Milestone | G37: Pathway | H37: Reached | I37: he will
A38: Ephrem | B38: Gobezie | C38: ephigo123@gmail.com | D38: +251918731166 | E38: =IF(ISNUMBER(MATCH(C38, 'Paid and Interested'!C:C, 0)), "Yes", "No") -> No | F38: Practice Quiz: Week 9, Week 9 Quiz, Week 9 Milestone, Week 9 Test | G38: Pathway | H38: Reached | I38: he will
A39: Rafat | B39: Kedir | C39: rafatk2021@gmail.com | D39: +251911470399 | E39: =IF(ISNUMBER(MATCH(C39, 'Paid and Interested'!C:C, 0)), "Yes", "No") -> No | F39: Practice Quiz: Week 9, Week 9 Quiz, Week 9 Milestone, Week 9 Test | G39: Pathway | H39: Reached | I39: he will
A40: Feruz | B40: Nesru | C40: seraphinadada@gmail.com | D40: +251910072535 | E40: =IF(ISNUMBER(MATCH(C40, 'Paid and Interested'!C:C, 0)), "Yes", "No") -> No | F40: Practice Quiz: Week 9, Week 9 Quiz, Week 9 Milestone, Week 9 Test | G40: Pathway | H40: Reached | I40: she will
A41: Ashenafi | B41: Asfaw | C41: asfawashenafi1371@gmail.com | D41: +251930755525 | E41: =IF(ISNUMBER(MATCH(C41, 'Paid and Interested'!C:C, 0)), "Yes", "No") -> No | F41: Week 9 Quiz, Week 9 Milestone, Week 9 Test | G41: Pathway | H41: Reached | I41: he will
A42: Metasebia | B42: Tilahun | C42: metasebiatilahun726@gmail.com | D42: +251947811321 | E42: =IF(ISNUMBER(MATCH(C42, 'Paid and Interested'!C:C, 0)), "Yes", "No") -> No | F42: Practice Quiz: Week 9, Week 9 Quiz, Week 9 Milestone, Week 9 Test | G42: Pathway | H42: Reached | I42: she will
A43: Abraham Mulugeta | B43: Adebash | C43: zeabrahammulugeta@gmail.com | D43: +251918968852 | E43: =IF(ISNUMBER(MATCH(C43, 'Paid and Interested'!C:C, 0)), "Yes", "No") -> No | F43: Week 9 Milestone, Week 9 Test | G43: Pathway | H43: Reached | I43: he will
A44: Lidya | B44: Nahom | C44: lidyanahom04@gmail.com | D44: +251961097887 | E44: =IF(ISNUMBER(MATCH(C44, 'Paid and Interested'!C:C, 0)), "Yes", "No") -> No | F44: Practice Quiz: Week 9, Week 9 Quiz, Week 9 Milestone, Week 9 Test | G44: Pathway | H44: Reached | I44: she will
A45: Lidiya | B45: Endale | C45: gracelidiya56@gmail.com | D45: +251712271351 | E45: =IF(ISNUMBER(MATCH(C45, 'Paid and Interested'!C:C, 0)), "Yes", "No") -> No | F45: Practice Quiz: Week 9, Week 9 Quiz, Week 9 Milestone, Week 9 Test | G45: Pathway | H45: Reached | I45: she will
A46: Ermias | B46: Mehreteab | C46: ermercy338@gmail.com | D46: +251973794050 | E46: =IF(ISNUMBER(MATCH(C46, 'Paid and Interested'!C:C, 0)), "Yes", "No") -> No | F46: Practice Quiz: Week 9, Week 9 Quiz, Week 9 Milestone, Week 9 Test | G46: Pathway | H46: Reached | I46: he will
A47: Tsion | B47: Gidey | C47: tsigiday42@gmail.com | D47: +251984659692 | E47: =IF(ISNUMBER(MATCH(C47, 'Paid and Interested'!C:C, 0)), "Yes", "No") -> No | F47: Practice Quiz: Week 9, Week 9 Quiz, Week 9 Milestone, Week 9 Test | G47: Pathway | H47: Reached | I47: Already done
A48: Ekram | B48: Gashaw | C48: ekramgashaw1@gmail.com | D48: +251908022125 | E48: =IF(ISNUMBER(MATCH(C48, 'Paid and Interested'!C:C, 0)), "Yes", "No") -> No | F48: Week 9 Quiz, Week 9 Milestone | G48: Pathway | H48: Reached | I48: she will
A49: Kibru | B49: Gebregeorgis | C49: kibrutsadik@gmail.com | D49: +251917266440 | E49: =IF(ISNUMBER(MATCH(C49, 'Paid and Interested'!C:C, 0)), "Yes", "No") -> No | F49: Practice Quiz: Week 9, Week 9 Quiz, Week 9 Milestone | G49: Pathway | H49: Reached | I49: he will
...

Sheet Girum
A1: First name | B1: Last name | C1: Email | D1: Contact phone | E1: Is Paid and Interested? | F1: Missing Assignments | G1: Catagory | H1: Call Status | I1: Comment
A2: WUDU | B2: TESFA | C2: wudutesfap@gmail.com | D2: +251967435502 | E2: =IF(ISNUMBER(MATCH(C2, 'Paid and Interested'!C:C, 0)), "Yes", "No") -> No | F2: Practice Quiz: Week 9, Week 9 Quiz, Week 9 Milestone, Week 9 Test | G2: Pathway | H2: Reached | I2: he will finnish
A3: Tinbit mandefro | B3: Mitiku | C3: mitikutinbit@gmail.com | D3: +251938842608 | E3: =IF(ISNUMBER(MATCH(C3, 'Paid and Interested'!C:C, 0)), "Yes", "No") -> No | F3: Practice Quiz: Week 9, Week 9 Quiz, Week 9 Milestone, Week 9 Test | G3: Pathway | H3: Reached | I3: she will finnish
A4: Kenenisa | B4: Jaleta | C4: miltolomite@gmail.com | D4: +25126778875 | E4: =IF(ISNUMBER(MATCH(C4, 'Paid and Interested'!C:C, 0)), "Yes", "No") -> No | F4: Practice Quiz: Week 9, Week 9 Quiz, Week 9 Milestone, Week 9 Test | G4: Pathway | H4: Reached | I4: he will finnish
A5: Natanim | B5: Aklilu | C5: natanimaklilu2@gmail.com | D5: +251937524509 | E5: =IF(ISNUMBER(MATCH(C5, 'Paid and Interested'!C:C, 0)), "Yes", "No") -> No | F5: Practice Quiz: Week 9, Week 9 Quiz, Week 9 Milestone, Week 9 Test | G5: Pathway | H5: Reached | I5: he will finnish
A6: Dawit | B6: Sisay | C6: dawitmelos55@gmail.com | D6: +251956701666 | E6: =IF(ISNUMBER(MATCH(C6, 'Paid and Interested'!C:C, 0)), "Yes", "No") -> No | F6: Practice Quiz: Week 9, Week 9 Quiz, Week 9 Milestone, Week 9 Test | G6: Pathway | H6: Reached | I6: he will finnish
A7: Kalkidan | B7: Abebe | C7: abebebikila988@gmail.com | D7: +251932178255 | E7: =IF(ISNUMBER(MATCH(C7, 'Paid and Interested'!C:C, 0)), "Yes", "No") -> No | F7: Practice Quiz: Week 9, Week 9 Quiz, Week 9 Milestone, Week 9 Test | G7: Pathway | H7: Reached | I7: she will finnish
A8: Abraham | B8: Alemayehu | C8: abrahamalemayehu52@gmail.com | D8: +251977626168 | E8: =IF(ISNUMBER(MATCH(C8, 'Paid and Interested'!C:C, 0)), "Yes", "No") -> No | F8: Practice Quiz: Week 9, Week 9 Quiz, Week 9 Milestone, Week 9 Test | G8: Pathway | H8: Reached | I8: he will finnish
A9: Abreham | B9: Abebe | C9: abrehamabebe1921@gmail.com | D9: +251930368324 | E9: =IF(ISNUMBER(MATCH(C9, 'Paid and Interested'!C:C, 0)), "Yes", "No") -> No | F9: Week 9 Milestone, Week 9 Test, Practice Quiz: Week 9, Week 9 Quiz | G9: Pathway | H9: Reached | I9: busy to submit
A10: Nayomi | B10: Yonas | C10: yonasnayomi@gmail.com | D10: +251962099731 | E10: =IF(ISNUMBER(MATCH(C10, 'Paid and Interested'!C:C, 0)), "Yes", "No") -> No | F10: Week 9 Milestone, Week 9 Test | G10: Pathway | H10: Reached | I10: she will finnish
A11: Heamen | B11: Daniel | C11: melshiewtegenge@gmail.com | D11: 934169021 | E11: =IF(ISNUMBER(MATCH(C11, 'Paid and Interested'!C:C, 0)), "Yes", "No") -> No | F11: Practice Quiz: Week 9, Week 9 Quiz, Week 9 Milestone, Week 9 Test | G11: Pathway | H11: Reached | I11: she will finish
A12: Abel | B12: Yitages | C12: abelyitages10@gmail.com | D12: 251985401417 | E12: =IF(ISNUMBER(MATCH(C12, 'Paid and Interested'!C:C, 0)), "Yes", "No") -> No | F12: Week 9 Milestone | G12: Pathway | H12: Reached | I12: he will finnish
A13: Abenet | B13: Shegaw | C13: abinetshegaw@gmail.com | D13: +251942869218 | E13: =IF(ISNUMBER(MATCH(C13, 'Paid and Interested'!C:C, 0)), "Yes", "No") -> No | F13: Week 9 Milestone, Week 9 Test | G13: Pathway | H13: Reached | I13: he will finnish
A14: Eyobed | B14: Alemayehu | C14: eyobalex7@gmail.com | D14: +251904858961 | E14: =IF(ISNUMBER(MATCH(C14, 'Paid and Interested'!C:C, 0)), "Yes", "No") -> No | F14: Practice Quiz: Week 9, Week 9 Milestone | G14: Pathway | H14: Reached | I14: he will finnish
A15: Yeabsira | B15: Yirdaw | C15: yeabsirayirdaw@gmail.com | D15: +251918713274 | E15: =IF(ISNUMBER(MATCH(C15, 'Paid and Interested'!C:C, 0)), "Yes", "No") -> No | F15: Week 9 Milestone | G15: Pathway | H15: Reached | I15: he will finnish
A16: Akotet | B16: Demise | C16: akotetshimelis@gmail.com | D16: +251908195066 | E16: =IF(ISNUMBER(MATCH(C16, 'Paid and Interested'!C:C, 0)), "Yes", "No") -> No | F16: Week 9 Milestone, Week 9 Test | G16: Pathway | H16: Reached | I16: she will finnish
A17: Barnabas | B17: Amede | C17: barnabasva1@gmail.com | D17: +251988980824 | E17: =IF(ISNUMBER(MATCH(C17, 'Paid and Interested'!C:C, 0)), "Yes", "No") -> No | F17: Practice Quiz: Week 9 | G17: Pathway | H17: Reached | I17: he will finnish
A18: Merdokios | B18: Abebayehu | C18: merdokiosa@gmail.com | D18: 935863319 | E18: =IF(ISNUMBER(MATCH(C18, 'Paid and Interested'!C:C, 0)), "Yes", "No") -> No | F18: Week 9 Milestone | G18: Pathway | H18: Reached | I18: he will finnish
A19: Selamawit | B19: Welday | C19: selamawitwelday70@gmail.com | D19: +251913250178 | E19: =IF(ISNUMBER(MATCH(C19, 'Paid and Interested'!C:C, 0)), "Yes", "No") -> No | F19: Week 9 Milestone | G19: Pathway | H19: Reached | I19: she will finnish
A20: Abdulkamil | B20: Kemal | C20: kamawesagn77@gmail.com | D20: +251919678829 | E20: =IF(ISNUMBER(MATCH(C20, 'Paid and Interested'!C:C, 0)), "Yes", "No") -> No | F20: Week 9 Milestone | G20: Pathway | H20: Reached | I20: he will finnish
A21: Haileslassie | B21: Gebremedhn | C21: haileslassiegebremedhn029@gmail.com | D21: +251904310657 | E21: =IF(ISNUMBER(MATCH(C21, 'Paid and Interested'!C:C, 0)), "Yes", "No") -> No | F21: Week 9 Milestone | G21: Pathway | H21: Reached | I21: he will finnish
A22: Yohana | B22: Getahun | C22: yohget01998@gmail.com | D22: +251977472326 | E22: =IF(ISNUMBER(MATCH(C22, 'Paid and Interested'!C:C, 0)), "Yes", "No") -> No | F22: Week 9 Milestone | G22: Pathway | H22: Reached | I22: he will finnish
A23: Nesredin | B23: Faris | C23: nesru16zeynu@gmail.com | D23: 974288845 | E23: =IF(ISNUMBER(MATCH(C23, 'Paid and Interested'!C:C, 0)), "Yes", "No") -> No | F23: Practice Quiz: Week 9 | G23: Pathway | H23: Reached | I23: he will finnish
A24: Kidus | B24: Nesibu | C24: kidusnesibualiyu@gmail.com | D24: +251929784808 | E24: =IF(ISNUMBER(MATCH(C24, 'Paid and Interested'!C:C, 0)), "Yes", "No") -> No | F24: Week 9 Milestone, Week 9 Test | G24: Pathway | H24: Reached | I24: he will finnish
A25: Gemechu | B25: Gadisa | C25: gamegbay3@gmail.com | D25: +251933851065 | E25: =IF(ISNUMBER(MATCH(C25, 'Paid and Interested'!C:C, 0)), "Yes", "No") -> No | F25: Week 9 Milestone | G25: Pathway | H25: Reached | I25: he will finnish
A26: Kalid | B26: Hassen | C26: kalidhassen028@gmail.com | D26: +251922579357 | E26: =IF(ISNUMBER(MATCH(C26, 'Paid and Interested'!C:C, 0)), "Yes", "No") -> No | F26: Week 9 Milestone | G26: Pathway | H26: Reached | I26: he will finnish
A27: Kidus | B27: Hassen | C27: kidushassen573@gmail.com | D27: +251940190730 | E27: =IF(ISNUMBER(MATCH(C27, 'Paid and Interested'!C:C, 0)), "Yes", "No") -> No | F27: Practice Quiz: Week 9, Week 9 Milestone | G27: Pathway | H27: Reached | I27: he will finnish
A28: Liya | B28: Wondmu | C28: liyawondmu030@gmail.com | D28: +251976008760 | E28: =IF(ISNUMBER(MATCH(C28, 'Paid and Interested'!C:C, 0)), "Yes", "No") -> No | F28: Practice Quiz: Week 9 | G28: Pathway | H28: Reached | I28: she will finnish
A29: Yeabsira | B29: Getachew | C29: yeabsiragetachew288@gmail.com | D29: +251995293895 | E29: =IF(ISNUMBER(MATCH(C29, 'Paid and Interested'!C:C, 0)), "Yes", "No") -> No | F29: Week 9 Milestone | G29: Pathway | H29: Reached | I29: she will finnish
A30: Hasinat | B30: Assefa | C30: hasumititi@gmail.com | D30: +251967846883 | E30: =IF(ISNUMBER(MATCH(C30, 'Paid and Interested'!C:C, 0)), "Yes", "No") -> No | F30: Practice Quiz: Week 9 | G30: Pathway | H30: Reached
A31: Amir | B31: Negash | C31: amirhassen790@gmail.com | D31: 967314406 | E31: =IF(ISNUMBER(MATCH(C31, 'Paid and Interested'!C:C, 0)), "Yes", "No") -> No | F31: Week 9 Milestone | G31: Pathway | H31: Reached | I31: he will finnish
A32: Frehiwot | B32: Zerihun | C32: frehiwotzerihun7@gmail.com | D32: +251973992859 | E32: =IF(ISNUMBER(MATCH(C32, 'Paid and Interested'!C:C, 0)), "Yes", "No") -> No | F32: Week 9 Milestone | G32: Pathway | H32: Reached | I32: she will finnish
A33: Yohanes | B33: Mesfin | C33: yohanesmesfin21@gmail.com | D33: 985376102 | E33: =IF(ISNUMBER(MATCH(C33, 'Paid and Interested'!C:C, 0)), "Yes", "No") -> No | F33: Practice Quiz: Week 9, Week 9 Milestone | G33: Pathway | H33: Reached | I33: he will finnish
A34: Faris | B34: Yeteshawork | C34: farisyeteshawork95@gmail.com | D34: +251910131492 | E34: =IF(ISNUMBER(MATCH(C34, 'Paid and Interested'!C:C, 0)), "Yes", "No") -> No | F34: Practice Quiz: Week 9, Week 9 Milestone | G34: Pathway | H34: Reached | I34: he will finnish
A35: Rediet | B35: Getaneh | C35: yerediet@gmail.com | D35: +251975255235 | E35: =IF(ISNUMBER(MATCH(C35, 'Paid and Interested'!C:C, 0)), "Yes", "No") -> No | F35: Week 9 Milestone | G35: Pathway | H35: Reached | I35: he will finnish
A36: Seble | B36: Dagnachew | C36: seblefeleke16@gmail.com | D36: +251952889761 | E36: =IF(ISNUMBER(MATCH(C36, 'Paid and Interested'!C:C, 0)), "Yes", "No") -> No | F36: Practice Quiz: Week 9, Week 9 Quiz, Week 9 Milestone, Week 9 Test | G36: Pathway | H36: Reached | I36: Not interested
A37: Liul | B37: Eshetu | C37: shetululee@gmail.com | D37: +251923341644 | E37: =IF(ISNUMBER(MATCH(C37, 'Paid and Interested'!C:C, 0)), "Yes", "No") -> No | F37: Week 9 Milestone, Week 9 Test, Practice Quiz: Week 9, Week 9 Quiz | G37: Pathway | H37: Reached | I37: Not interetsed
A38: Mekdlawit | B38: Sule | C38: mhkgirls@gmail.com | D38: +251976765171 | E38: =IF(ISNUMBER(MATCH(C38, 'Paid and Interested'!C:C, 0)), "Yes", "No") -> No | F38: Week 9 Quiz, Week 9 Milestone, Week 9 Test | G38: Pathway | H38: Reached | I38: she will finnish
A39: Eleni | B39: Tewodros | C39: elenitewodros9@gmail.com | D39: +251951583387 | E39: =IF(ISNUMBER(MATCH(C39, 'Paid and Interested'!C:C, 0)), "Yes", "No") -> No | F39: Week 9 Milestone, Week 9 Test, Practice Quiz: Week 9, Week 9 Quiz | G39: Pathway | H39: Phone Not Working
A40: Beamlak | B40: Jembere | C40: bkg4281@gmail.com | D40: +251985414412 | E40: =IF(ISNUMBER(MATCH(C40, 'Paid and Interested'!C:C, 0)), "Yes", "No") -> No | F40: Practice Quiz: Week 9, Week 9 Quiz, Week 9 Milestone, Week 9 Test | G40: Pathway | H40: Phone Not Working
...

Sheet Consolidated
A1: First name | B1: Last name | C1: Email | D1: Contact phone | E1: Is Paid and Interested? | F1: Missing Assignments | G1: Program | H1: Call Status | I1: Comment
A2: yoseph legesse | B2: abrha | C2: aregawiesayas@gmail.com | D2: +251996165586 | E2: =IF(ISNUMBER(MATCH(C2, 'Paid and Interested'!C:C, 0)), "Yes", "No") -> No | F2: Week 9 Milestone, Week 9 Test, Practice Quiz: Week 9, Week 9 Quiz | G2: Pathway | H2: Wrong Person
A3: ezana | B3: ketema | C3: ezanaketema22@gmail.com | D3: 251934432842 | E3: =IF(ISNUMBER(MATCH(C3, 'Paid and Interested'!C:C, 0)), "Yes", "No") -> No | F3: Practice Quiz: Week 9, Week 9 Quiz, Week 9 Milestone, Week 9 Test | G3: Pathway | H3: Reached | I3: he said okay
A4: Destaw Gisme | B4: Mulachew | C4: destawg@gmail.com | D4: +251918489684 | E4: =IF(ISNUMBER(MATCH(C4, 'Paid and Interested'!C:C, 0)), "Yes", "No") -> No | F4: Practice Quiz: Week 9, Week 9 Quiz, Week 9 Milestone, Week 9 Test | G4: Pathway | H4: Reached | I4: he said okay
A5: Bitew | B5: Ababayehu | C5: bict1626@gmail.com | D5: +251949625344 | E5: =IF(ISNUMBER(MATCH(C5, 'Paid and Interested'!C:C, 0)), "Yes", "No") -> No | F5: Week 9 Milestone, Week 9 Test, Practice Quiz: Week 9, Week 9 Quiz | G5: Pathway | H5: Reached | I5: he said okay
A6: Yitbarek | B6: Denbu | C6: yitbareksebsibe9@gmail.com | D6: 919410818 | E6: =IF(ISNUMBER(MATCH(C6, 'Paid and Interested'!C:C, 0)), "Yes", "No") -> No | F6: Week 9 Milestone, Week 9 Test, Practice Quiz: Week 9, Week 9 Quiz | G6: Pathway | H6: Reached | I6: he said okay
A7: Mubarek | B7: Hassen | C7: mubeman63@gmail.com | D7: +251965030079 | E7: =IF(ISNUMBER(MATCH(C7, 'Paid and Interested'!C:C, 0)), "Yes", "No") -> No | F7: Week 9 Milestone, Week 9 Test, Practice Quiz: Week 9, Week 9 Quiz | G7: Pathway | H7: Reached | I7: he has paused the course
A8: Muzeyfi | B8: Mahadi | C8: mmuzeyfi@gmail.com | D8: +251975284215 | E8: =IF(ISNUMBER(MATCH(C8, 'Paid and Interested'!C:C, 0)), "Yes", "No") -> No | F8: Week 9 Milestone, Week 9 Test, Practice Quiz: Week 9, Week 9 Quiz | G8: Pathway | H8: Reached | I8: he said okay
A9: Nebil | B9: Ahmed | C9: nebilnasir24@gmail.com | D9: +251994101121 | E9: =IF(ISNUMBER(MATCH(C9, 'Paid and Interested'!C:C, 0)), "Yes", "No") -> No | F9: Week 9 Milestone, Week 9 Test, Practice Quiz: Week 9, Week 9 Quiz | G9: Pathway | H9: Reached | I9: he said okay
A10: Siraj | B10: Hassen | C10: sifrajhassen@gmail.com | D10: +251984131188 | E10: =IF(ISNUMBER(MATCH(C10, 'Paid and Interested'!C:C, 0)), "Yes", "No") -> No | F10: Week 9 Milestone, Week 9 Test, Practice Quiz: Week 9, Week 9 Quiz | G10: Pathway | H10: Reached | I10: he is outside from Addis
A11: Addis | B11: Nigatu | C11: addishailu992@gmail.com | D11: +251945961714 | E11: =IF(ISNUMBER(MATCH(C11, 'Paid and Interested'!C:C, 0)), "Yes", "No") -> No | F11: Week 9 Milestone, Week 9 Test, Practice Quiz: Week 9, Week 9 Quiz | G11: Pathway | H11: Reached | I11: he said okay
A12: Biruk Abera | B12: Gebra | C12: birukaberagebra@gmail.com | D12: +251929346733 | E12: =IF(ISNUMBER(MATCH(C12, 'Paid and Interested'!C:C, 0)), "Yes", "No") -> No | F12: Practice Quiz: Week 9, Week 9 Quiz, Week 9 Milestone, Week 9 Test | G12: Pathway | H12: Reached | I12: he said okay
A13: Yohannis | B13: Million | C13: yohannismillion003@gmail.com | D13: +251994943497 | E13: =IF(ISNUMBER(MATCH(C13, 'Paid and Interested'!C:C, 0)), "Yes", "No") -> No | F13: Week 9 Milestone, Week 9 Test, Practice Quiz: Week 9, Week 9 Quiz | G13: Pathway | H13: Reached | I13: he's too busy to continue the course
A14: Habtamu | B14: Mune | C14: habtamu122124s@gmail.com | D14: +251939778240 | E14: =IF(ISNUMBER(MATCH(C14, 'Paid and Interested'!C:C, 0)), "Yes", "No") -> No | F14: Week 9 Milestone, Week 9 Test, Practice Quiz: Week 9, Week 9 Quiz | G14: Pathway | H14: Reached | I14: he's not intersted
A15: Ruth | B15: Getu | C15: rudygetu88@gmail.com | D15: +251944714263 | E15: =IF(ISNUMBER(MATCH(C15, 'Paid and Interested'!C:C, 0)), "Yes", "No") -> No | F15: Practice Quiz: Week 9, Week 9 Quiz, Week 9 Milestone, Week 9 Test | G15: Pathway | H15: Reached | I15: she's not interested
A16: Gedion | B16: Kifle | C16: gedionkifle0@gmail.com | D16: +251961099526 | E16: =IF(ISNUMBER(MATCH(C16, 'Paid and Interested'!C:C, 0)), "Yes", "No") -> No | F16: Week 9 Milestone, Week 9 Test, Practice Quiz: Week 9, Week 9 Quiz | G16: Pathway | H16: Reached | I16: he said okay
A17: Meron | B17: Zelalem | C17: haymikebede3@gmail.com | D17: +251929259929 | E17: =IF(ISNUMBER(MATCH(C17, 'Paid and Interested'!C:C, 0)), "Yes", "No") -> No | F17: Week 9 Milestone, Week 9 Test, Practice Quiz: Week 9, Week 9 Quiz | G17: Pathway | H17: Reached | I17: she said okay
A18: Bemnet | B18: Engdashet | C18: bemnetengda45@gmail.com | D18: +251912206321 | E18: =IF(ISNUMBER(MATCH(C18, 'Paid and Interested'!C:C, 0)), "Yes", "No") -> No | F18: Practice Quiz: Week 9, Week 9 Quiz, Week 9 Milestone, Week 9 Test | G18: Pathway | H18: Reached | I18: she isn't interested
... A23: Gidyelem | B23: Kelecha | C23: shibugidyelem@gmail.com | D23: +251992524875 | E23: =IF(ISNUMBER(MATCH(C23, 'Paid and Interested'!C:C, 0)), "Yes", "No") -> No | F23: Week 9 Milestone, Week 9 Test, Practice Quiz: Week 9, Week 9 Quiz | G23: Pathway | H23: Reached | I23: he's not interested
A24: Kirubel | B24: Hailu | C24: kirubel.seifu.great@gmail.com | D24: 909780413 | E24: =IF(ISNUMBER(MATCH(C24, 'Paid and Interested'!C:C, 0)), "Yes", "No") -> No | F24: Week 9 Milestone, Week 9 Test, Practice Quiz: Week 9, Week 9 Quiz | G24: Pathway | H24: Reached | I24: he said okay
A25: Naol | B25: Degol | C25: naolde812@gmail.com | D25: +251976029568 | E25: =IF(ISNUMBER(MATCH(C25, 'Paid and Interested'!C:C, 0)), "Yes", "No") -> No | F25: Week 9 Milestone, Week 9 Test, Practice Quiz: Week 9, Week 9 Quiz | G25: Pathway | H25: Reached | I25: he's not interested
A26: Habiba | B26: Ashref | C26: ashrefhabiba08@gmail.com | D26: +251912382222 | E26: =IF(ISNUMBER(MATCH(C26, 'Paid and Interested'!C:C, 0)), "Yes", "No") -> No | F26: Week 9 Milestone, Week 9 Test, Practice Quiz: Week 9, Week 9 Quiz | G26: Pathway | H26: Reached | I26: she wants to apply for the next cohort
A27: Hakimiyas | B27: Yilma | C27: kemeshgale@gmail.com | D27: 911918308 | E27: =IF(ISNUMBER(MATCH(C27, 'Paid and Interested'!C:C, 0)), "Yes", "No") -> No | F27: Practice Quiz: Week 9, Week 9 Quiz, Week 9 Milestone, Week 9 Test | G27: Pathway | H27: Reached | I27: he wants to apply for the next cohort
A28: Mikiyas | B28: Muluneh | C28: mulumiki4@gmail.com | D28: +251927990402 | E28: =IF(ISNUMBER(MATCH(C28, 'Paid and Interested'!C:C, 0)), "Yes", "No") -> No | F28: Week 9 Milestone, Week 9 Test, Practice Quiz: Week 9, Week 9 Quiz | G28: Pathway | H28: Reached | I28: he's not in Addis
A29: Kirubel | B29: Tesfaye | C29: tkirubel648@gmail.com | D29: +251939993088 | E29: =IF(ISNUMBER(MATCH(C29, 'Paid and Interested'!C:C, 0)), "Yes", "No") -> No | F29: Week 9 Milestone, Week 9 Test, Practice Quiz: Week 9, Week 9 Quiz | G29: Pathway | H29: Reached | I29: he wants to apply for the next cohort
A30: yohannes | B30: kebede | C30: yohaneskebedejo15@gmail.com | D30: +251935551413 | E30: =IF(ISNUMBER(MATCH(C30, 'Paid and Interested'!C:C, 0)), "Yes", "No") -> No | F30: Week 9 Milestone, Week 9 Test, Practice Quiz: Week 9, Week 9 Quiz | G30: Pathway | H30: Reached | I30: he's not in Addis
A31: Intisar | B31: Shemsu | C31: intisarshemsu2017gmail.com@gmail.com | D31: +251975184414 | E31: =IF(ISNUMBER(MATCH(C31, 'Paid and Interested'!C:C, 0)), "Yes", "No") -> No | F31: Week 9 Milestone, Week 9 Test, Practice Quiz: Week 9, Week 9 Quiz | G31: Pathway | H31: Reached | I31: she's not interested
A32: Yordanos | B32: Shemsedien | C32: yordanosshemsedin901@gmail.com | D32: +251901859818 | E32: =IF(ISNUMBER(MATCH(C32, 'Paid and Interested'!C:C, 0)), "Yes", "No") -> No | F32: Week 9 Milestone, Week 9 Test, Practice Quiz: Week 9, Week 9 Quiz | G32: Pathway | H32: Reached | I32: she's not in Addis
A33: REDIET TILAHUN | B33: AYELE | C33: rediettilahun10@gmail.com | D33: +251911172398 | E33: =IF(ISNUMBER(MATCH(C33, 'Paid and Interested'!C:C, 0)), "Yes", "No") -> No | F33: Week 9 Milestone, Week 9 Test, Practice Quiz: Week 9, Week 9 Quiz | G33: Pathway | H33: Reached | I33: he is too busy to continue the course
A34: Mengistu | B34: Tegegne | C34: tegegnem83@gmail.com | D34: 919698237 | E34: =IF(ISNUMBER(MATCH(C34, 'Paid and Interested'!C:C, 0)), "Yes", "No") -> No | F34: Week 9 Milestone, Week 9 Test, Practice Quiz: Week 9, Week 9 Quiz | G34: Pathway | H34: Reached | I34: he's not in Addis
A35: Blen | B35: Gebremariam | C35: bilublen20@gmail.com | D35: +251966888442 | E35: =IF(ISNUMBER(MATCH(C35, 'Paid and Interested'!C:C, 0)), "Yes", "No") -> No | F35: Week 9 Milestone, Week 9 Test, Practice Quiz: Week 9, Week 9 Quiz | G35: Pathway | H35: Reached | I35: she said okay
A36: Misganaw | B36: Yehuala | C36: asnakemisgana88@gmail.com | D36: +251913618893 | E36: =IF(ISNUMBER(MATCH(C36, 'Paid and Interested'!C:C, 0)), "Yes", "No") -> No | F36: Week 9 Milestone, Week 9 Test, Practice Quiz: Week 9, Week 9 Quiz | G36: Pathway | H36: Reached | I36: he will come to the hub
A37: Hanan | B37: Kebede | C37: hananitakebede12@gmail.com | D37: +251946409290 | E37: =IF(ISNUMBER(MATCH(C37, 'Paid and Interested'!C:C, 0)), "Yes", "No") -> No | F37: Week 9 Milestone, Week 9 Test, Practice Quiz: Week 9, Week 9 Quiz | G37: Pathway | H37: Reached | I37: email wasn't working
A38: Werkineh Gebermichael | B38: Welde | C38: werkinehgmichael10@gmail.com | D38: +251903096549 | E38: =IF(ISNUMBER(MATCH(C38, 'Paid and Interested'!C:C, 0)), "Yes", "No") -> No | F38: Week 9 Milestone, Week 9 Test, Practice Quiz: Week 9, Week 9 Quiz | G38: Pathway | H38: Reached | I38: he said okay
A39: Getnet | B39: Demissie | C39: getnetmulugeta2000@gmail.com | D39: 964865694 | E39: =IF(ISNUMBER(MATCH(C39, 'Paid and Interested'!C:C, 0)), "Yes", "No") -> No | F39: Week 9 Milestone, Week 9 Test, Practice Quiz: Week 9, Week 9 Quiz | G39: Pathway | H39: Reached | I39: he might finish the assignments
A40: Dagmawi | B40: Tesfaye | C40: dagmawitesfaye1318@gmail.com | D40: +251919183460 | E40: =IF(ISNUMBER(MATCH(C40, 'Paid and Interested'!C:C, 0)), "Yes", "No") -> No | F40: Week 9 Milestone, Week 9 Test, Practice Quiz: Week 9, Week 9 Quiz | G40: Pathway | H40: Reached | I40: he said okay
A41: Leul | B41: Yonas | C41: lecrae12345678@gmail.com | D41: +251909121415 | E41: =IF(ISNUMBER(MATCH(C41, 'Paid and Interested'!C:C, 0)), "Yes", "No") -> No | F41: Week 9 Milestone, Week 9 Test, Practice Quiz: Week 9, Week 9 Quiz | G41: Pathway | H41: Reached | I41: he's not interested
A42: Ruth | B42: Getachew | C42: ruthgetachew49@gmail.com | D42: +251946362757 | E42: =IF(ISNUMBER(MATCH(C42, 'Paid and Interested'!C:C, 0)), "Yes", "No") -> No | F42: Practice Quiz: Week 9, Week 9 Quiz, Week 9 Milestone, Week 9 Test | G42: Pathway | H42: Reached | I42: she's not in Addis
A43: Kenesa | B43: Tesfaye | C43: travtube43@gmail.com | D43: +251977840440 | E43: =IF(ISNUMBER(MATCH(C43, 'Paid and Interested'!C:C, 0)), "Yes", "No") -> No | F43: Week 9 Milestone, Week 9 Test, Practice Quiz: Week 9, Week 9 Quiz | G43: Pathway | H43: Reached | I43: he's not in Addis
A44: Eliyas | B44: Dejena | C44: eliyasdejena96@gmail.com | D44: +251991122060 | E44: =IF(ISNUMBER(MATCH(C44, 'Paid and Interested'!C:C, 0)), "Yes", "No") -> No | F44: Week 9 Milestone, Week 9 Test, Practice Quiz: Week 9, Week 9 Quiz | G44: Pathway | H44: Reached | I44: his email is not working
...

Sheet Interested learners after the c
A1: First name | B1: Last name | C1: Email | D1: Contact phone | E1: Is Paid and Interested? | F1: Missing Assignments | G1: Program | H1: Call Status | I1: Comment
A2: yoseph legesse | B2: abrha | C2: aregawiesayas@gmail.com | D2: +251996165586 | E2: =IF(ISNUMBER(MATCH(C2, 'Paid and Interested'!C:C, 0)), "Yes", "No") -> No | F2: Week 9 Milestone, Week 9 Test, Practice Quiz: Week 9, Week 9 Quiz | G2: Pathway | H2: Wrong Person
A3: ezana | B3: ketema | C3: ezanaketema22@gmail.com | D3: 251934432842 | E3: =IF(ISNUMBER(MATCH(C3, 'Paid and Interested'!C:C, 0)), "Yes", "No") -> No | F3: Practice Quiz: Week 9, Week 9 Quiz, Week 9 Milestone, Week 9 Test | G3: Pathway | H3: Reached | I3: he said okay
A4: Destaw Gisme | B4: Mulachew | C4: destawg@gmail.com | D4: +251918489684 | E4: =IF(ISNUMBER(MATCH(C4, 'Paid and Interested'!C:C, 0)), "Yes", "No") -> No | F4: Practice Quiz: Week 9, Week 9 Quiz, Week 9 Milestone, Week 9 Test | G4: Pathway | H4: Reached | I4: he said okay
A5: Bitew | B5: Ababayehu | C5: bict1626@gmail.com | D5: +251949625344 | E5: =IF(ISNUMBER(MATCH(C5, 'Paid and Interested'!C:C, 0)), "Yes", "No") -> No | F5: Week 9 Milestone, Week 9 Test, Practice Quiz: Week 9, Week 9 Quiz | G5: Pathway | H5: Reached | I5: he said okay
A6: Yitbarek | B6: Denbu | C6: yitbareksebsibe9@gmail.com | D6: 919410818 | E6: =IF(ISNUMBER(MATCH(C6, 'Paid and Interested'!C:C, 0)), "Yes", "No") -> No | F6: Week 9 Milestone, Week 9 Test, Practice Quiz: Week 9, Week 9 Quiz | G6: Pathway | H6: Reached | I6: he said okay
A7: Muzeyfi | B7: Mahadi | C7: mmuzeyfi@gmail.com | D7: +251975284215 | E7: =IF(ISNUMBER(MATCH(C7, 'Paid and Interested'!C:C, 0)), "Yes", "No") -> No | F7: Week 9 Milestone, Week 9 Test, Practice Quiz: Week 9, Week 9 Quiz | G7: Pathway | H7: Reached | I7: he said okay
A8: Nebil | B8: Ahmed | C8: nebilnasir24@gmail.com | D8: +251994101121 | E8: =IF(ISNUMBER(MATCH(C8, 'Paid and Interested'!C:C, 0)), "Yes", "No") -> No | F8: Week 9 Milestone, Week 9 Test, Practice Quiz: Week 9, Week 9 Quiz | G8: Pathway | H8: Reached | I8: he said okay
A9: Addis | B9: Nigatu | C9: addishailu992@gmail.com | D9: +251945961714 | E9: =IF(ISNUMBER(MATCH(C9, 'Paid and Interested'!C:C, 0)), "Yes", "No") -> No | F9: Week 9 Milestone, Week 9 Test, Practice Quiz: Week 9, Week 9 Quiz | G9: Pathway | H9: Reached | I9: he said okay
